Workbook
Name solver_lhs5: 'Эконом рост'!$B$8
Name solver_lhs4: 'Эконом рост'!$B$7
Name solver_lhs7: 'Эконом рост'!$B$9
Name solver_lhs3: 'Эконом рост'!$B$7
Name solver_lhs2: 'Эконом рост'!$B$16
Name solver_lhs1: 'Эконом рост'!$B$16
Name solver_lhs8: 'Эконом рост'!$B$9
Name solver_opt: 'Эконом рост'!$B$24
Name solver_lhs6: 'Эконом рост'!$B$8

Sheet Sources_Notes
B1: Item
A2: Project | B2: Germany
A3: Methodology (SNA/ESA) | B3: ESA 2010 (EU standard). Germany: Destatis (VGR).
A4: BoP methodology | B4: BPM6. Compiler: Deutsche Bundesbank.
A5: Key data sources | B5: - Eurostat: nama_10_gdp (GDP & components), gov_10a_main (GG finances), teina110 (GDP deflator), prc_hicp_aind (HICP) - Destatis: Producer Price Index, national accounts notes - Deutsche Bundesbank: Balance of Payments (current, capital, financial, reserves)
A6: Units & prices | B6: Use CURRENT PRICES: million EUR (CP_MEUR) for nominal identities. Labour in thousand persons.

Sheet ВВП (расходы)
A1: period | B1: Gross domestic product at market prices – Germany (Eurostat/nama_10_gdp/A.CP_MEUR.B1GQ.DE) | C1: Annual – Current prices, million euro – Household and NPISH final consumption expenditure – Germany (Eurostat/nama_10_gdp/A.CP_MEUR.P31_S14_S15.DE) | D1: Annual – Current prices, million euro – Final consumption expenditure of general government – Germany (Eurostat/nama_10_gdp/A.CP_MEUR.P3_S13.DE) | E1: Annual – Current prices, million euro – Gross fixed capital formation – Germany (Eurostat/nama_10_gdp/A.CP_MEUR.P51G.DE) | F1: Annual – Current prices, million euro – Changes in inventories and acquisitions less disposals of valuables – Germany (Eurostat/nama_10_gdp/A.CP_MEUR.P52_P53.DE) | G1: Annual – Current prices, million euro – Exports of goods and services – Germany (Eurostat/nama_10_gdp/A.CP_MEUR.P6.DE) | H1: Annual – Current prices, million euro – Imports of goods and services – Germany (Eurostat/nama_10_gdp/A.CP_MEUR.P7.DE)
B2: ВВП=E | C2: C | D2: G | F2: I | G2: Ex | H2: Im | J2: ВВП (по расходам) | K2: Проверка
A3: 1991 | B3: 1517932.9 | C3: 841942.9 | D3: 285553.8 | E3: 377047 | F3: 21030.2 | G3: 357716.2 | H3: 365357.4 | J3: =C3+F3+(D3+E3)+(G3-H3) -> 1517932.7 | K3: =IF(INT(J3)=INT(B3),"верно","неверно") -> верно
A4: 1992 | B4: 1655317.2 | C4: 918819.2 | D4: 320475.5 | E4: 413970.1 | F4: 10410.8 | G4: 365652.1 | H4: 374010.5 | J4: =C4+F4+(D4+E4)+(G4-H4) -> 1655317.2 | K4: =IF(INT(J4)=INT(B4),"верно","неверно") -> верно
A5: 1993 | B5: 1774986.2 | C5: 999493.6 | D5: 346620 | E5: 425317.3 | F5: 3401.8 | G5: 352849.9 | H5: 352696.4 | J5: =C5+F5+(D5+E5)+(G5-H5) -> 1774986.2 | K5: =IF(INT(J5)=INT(B5),"верно","неверно") -> верно
A6: 1994 | B6: 1867918.1 | C6: 1043437.4 | D6: 363721.8 | E6: 448761.9 | F6: 9836.4 | G6: 384897.7 | H6: 382737.1 | J6: =C6+F6+(D6+E6)+(G6-H6) -> 1867918.1 | K6: =IF(INT(J6)=INT(B6),"верно","неверно") -> верно
A7: 1995 | B7: 1983157.1 | C7: 1101226.1 | D7: 389434.4 | E7: 465341 | F7: 20077.6 | G7: 426012.5 | H7: 418934.4 | J7: =C7+F7+(D7+E7)+(G7-H7) -> 1983157.2 | K7: =IF(INT(J7)=INT(B7),"верно","неверно") -> верно | L7: =H7/'Рынок труда'!H3 -> 5489.0385
A8: 1996 | B8: 1975310.3 | C8: 1106042 | D8: 392800.5 | E8: 452996.2 | F8: 10419.6 | G8: 440142 | H8: 427090.1 | J8: =C8+F8+(D8+E8)+(G8-H8) -> 1975310.2 | K8: =IF(INT(J8)=INT(B8),"верно","неверно") -> верно | L8: =H8/'Рынок труда'!H4 -> 5538.3531
A9: 1997 | B9: 1958621.6 | C9: 1097259.4 | D9: 382919.8 | E9: 442112.1 | F9: 16303.8 | G9: 483807 | H9: 463780.5 | J9: =C9+F9+(D9+E9)+(G9-H9) -> 1958621.6 | K9: =IF(INT(J9)=INT(B9),"верно","неверно") -> верно | L9: =H9/'Рынок труда'!H5 -> 5904.647
A10: 1998 | B10: 2008652.6 | C10: 1114882.6 | D10: 387074.2 | E10: 455981.6 | F10: 27316.3 | G10: 515423.5 | H10: 492025.6 | J10: =C10+F10+(D10+E10)+(G10-H10) -> 2008652.6 | K10: =IF(INT(J10)=INT(B10),"верно","неверно") -> верно | L10: =H10/'Рынок труда'!H6 -> 6135.6711
A11: 1999 | B11: 2077240 | C11: 1164899 | D11: 407595 | E11: 474306 | F11: 19212 | G11: 540703 | H11: 529475 | J11: =C11+F11+(D11+E11)+(G11-H11) -> 2077240 | K11: =IF(INT(J11)=INT(B11),"верно","неверно") -> верно | L11: =H11/'Рынок труда'!H7 -> 6464.8962
A12: 2000 | B12: 2129660 | C12: 1201814 | D12: 413966 | E12: 487329 | F12: 23022 | G12: 632097 | H12: 628568 | J12: =C12+F12+(D12+E12)+(G12-H12) -> 2129660 | K12: =IF(INT(J12)=INT(B12),"верно","неверно") -> верно | L12: =H12/'Рынок труда'!H8 -> 7460.2165
A13: 2001 | B13: 2195530 | C13: 1238791 | D13: 422652 | E13: 472991 | F13: 26812 | G13: 670963 | H13: 636679 | J13: =C13+F13+(D13+E13)+(G13-H13) -> 2195530 | K13: =IF(INT(J13)=INT(B13),"верно","неверно") -> верно | L13: =H13/'Рынок труда'!H9 -> 7434.7989
A14: 2002 | B14: 2223360 | C14: 1250939 | D14: 434366 | E14: 442153 | F14: 5893 | G14: 693476 | H14: 603467 | J14: =C14+F14+(D14+E14)+(G14-H14) -> 2223360 | K14: =IF(INT(J14)=INT(B14),"верно","неверно") -> верно | L14: =H14/'Рынок труда'!H10 -> 7063.1328
A15: 2003 | B15: 2240810 | C15: 1282424 | D15: 438568 | E15: 431667 | F15: 7008 | G15: 700653 | H15: 619510 | J15: =C15+F15+(D15+E15)+(G15-H15) -> 2240810 | K15: =IF(INT(J15)=INT(B15),"верно","неверно") -> верно | L15: =H15/'Рынок труда'!H11 -> 7289.4678
A16: 2004 | B16: 2293040 | C16: 1306221 | D16: 436826 | E16: 431813 | F16: 4355 | G16: 778148 | H16: 664323 | J16: =C16+F16+(D16+E16)+(G16-H16) -> 2293040 | K16: =IF(INT(J16)=INT(B16),"верно","неверно") -> верно | L16: =H16/'Рынок труда'!H12 -> 7727.0221
A17: 2005 | B17: 2325710 | C17: 1334453 | D17: 440326 | E17: 436406 | F17: -672 | G17: 836166 | H17: 720969 | J17: =C17+F17+(D17+E17)+(G17-H17) -> 2325710 | K17: =IF(INT(J17)=INT(B17),"верно","неверно") -> верно | L17: =H17/'Рынок труда'!H13 -> 8312.2233
A18: 2006 | B18: 2426180 | C18: 1369999 | D18: 447752 | E18: 472193 | F18: 10567 | G18: 945469 | H18: 819800 | J18: =C18+F18+(D18+E18)+(G18-H18) -> 2426180 | K18: =IF(INT(J18)=INT(B18),"верно","неверно") -> верно | L18: =H18/'Рынок труда'!H14 -> 9100.7993
... A36: 2024 | B36: 4305260 | C36: 2270376 | D36: 960248 | E36: 898489 | F36: 7188 | G36: 1799605 | H36: 1630646 | J36: =C36+F36+(D36+E36)+(G36-H36) -> 4305260 | K36: =IF(INT(J36)=INT(B36),"верно","неверно") -> верно | L36: =H36/'Рынок труда'!H32 -> 15155.548

Sheet ВВП (доходы)
A1: period | B1: Annual – Current prices, million euro – Operating surplus and mixed income, gross – Germany (Eurostat/nama_10_gdp/A.CP_MEUR.B2A3G.DE) | C1: Annual – Current prices, million euro – Compensation of employees – Germany (Eurostat/nama_10_gdp/A.CP_MEUR.D1.DE) | D1: Annual – Current prices, million euro – Taxes on production and imports less subsidies – Germany (Eurostat/nama_10_gdp/A.CP_MEUR.D2X3.DE)
B2: Вал прибыль + Вал смеш прибыль | C2: Оплата труда | D2: Чистые налоги на произв-во и импорт | F2: ВВП (доходы) | G2: Проверка
A3: 1991 | B3: 576038.4 | C3: 823078.6 | D3: 118815.9 | F3: =B3+C3+D3 -> 1517932.9 | G3: =IF(INT(F3)=INT('ВВП (расходы)'!J3),"верно","неверно") -> верно
A4: 1992 | B4: 614249.3 | C4: 906914.7 | D4: 134153.2 | F4: =B4+C4+D4 -> 1655317.2 | G4: =IF(INT(F4)=INT('ВВП (расходы)'!J4),"верно","неверно") -> верно
A5: 1993 | B5: 655285.6 | C5: 969875.1 | D5: 149825.5 | F5: =B5+C5+D5 -> 1774986.2 | G5: =IF(INT(F5)=INT('ВВП (расходы)'!J5),"верно","неверно") -> верно
A6: 1994 | B6: 704209.7 | C6: 1002603.8 | D6: 161104.7 | F6: =B6+C6+D6 -> 1867918.2 | G6: =IF(INT(F6)=INT('ВВП (расходы)'!J6),"верно","неверно") -> верно
A7: 1995 | B7: 748619.3 | C7: 1069362.9 | D7: 165174.9 | F7: =B7+C7+D7 -> 1983157.1 | G7: =IF(INT(F7)=INT('ВВП (расходы)'!J7),"верно","неверно") -> верно
A8: 1996 | B8: 753667.3 | C8: 1059052.9 | D8: 162590.1 | F8: =B8+C8+D8 -> 1975310.3 | G8: =IF(INT(F8)=INT('ВВП (расходы)'!J8),"верно","неверно") -> верно
A9: 1997 | B9: 760229.1 | C9: 1034071.5 | D9: 164321 | F9: =B9+C9+D9 -> 1958621.6 | G9: =IF(INT(F9)=INT('ВВП (расходы)'!J9),"верно","неверно") -> верно
A10: 1998 | B10: 785183.3 | C10: 1053703.6 | D10: 169765.7 | F10: =B10+C10+D10 -> 2008652.6 | G10: =IF(INT(F10)=INT('ВВП (расходы)'!J10),"верно","неверно") -> верно
A11: 1999 | B11: 795641 | C11: 1090834 | D11: 190765 | F11: =B11+C11+D11 -> 2077240 | G11: =IF(INT(F11)=INT('ВВП (расходы)'!J11),"верно","неверно") -> верно
A12: 2000 | B12: 798219 | C12: 1134632 | D12: 196809 | F12: =B12+C12+D12 -> 2129660 | G12: =IF(INT(F12)=INT('ВВП (расходы)'!J12),"верно","неверно") -> верно
A13: 2001 | B13: 842341 | C13: 1152309 | D13: 200880 | F13: =B13+C13+D13 -> 2195530 | G13: =IF(INT(F13)=INT('ВВП (расходы)'!J13),"верно","неверно") -> верно
A14: 2002 | B14: 859088 | C14: 1160285 | D14: 203987 | F14: =B14+C14+D14 -> 2223360 | G14: =IF(INT(F14)=INT('ВВП (расходы)'!J14),"верно","неверно") -> верно
... A36: 2024 | B36: 1571962 | C36: 2350171 | D36: 383127 | F36: =B36+C36+D36 -> 4305260 | G36: =IF(INT(F36)=INT('ВВП (расходы)'!J36),"верно","неверно") -> верно

Sheet Секторный Баланс
A1: period | B1: Annual – Current prices, million euro – Paid – Saving, gross – Total economy – Germany (Eurostat/nasa_10_nf_tr/A.CP_MEUR.PAID.B8G.S1.DE) | C1: Annual – Current prices, million euro – Paid – Saving, gross – General government – Germany (Eurostat/nasa_10_nf_tr/A.CP_MEUR.PAID.B8G.S13.DE) | K1: Проверка
B2: Вал сбережения (вся экономика) | C2: Вал сбережения (гос-во) | D2: S | E2: I total | F2: Nx=Ex-Im | G2: δ | H2: S=I_total​−δ+NX | I2: I | J2: Im-Ex | K2: I − [S + δ + (Im − Ex)] | L2: I_total − [S + δ + (Im − Ex)]
A3: 1995 | B3: 460328 | C3: 10938 | D3: =B3-C3 -> 449390 | E3: ='ВВП (расходы)'!E3+'ВВП (расходы)'!I3 -> 377047 | F3: ='ВВП (расходы)'!G3-'ВВП (расходы)'!H3 -> -7641.2 | G3: ='ГосБюджет'!S3 -> -289814.5 | H3: =E3-G3+F3 -> 659220.3 | I3: ='ВВП (расходы)'!E3+'ВВП (расходы)'!F3 -> 398077.2 | J3: ='ВВП (расходы)'!H3-'ВВП (расходы)'!G3 -> 7641.2 | K3: =I3-(D3+'ГосБюджет'!S3+J3) -> 230860.5 | L3: =E3-(H3+G3+J3) -> 0 | M3: попробовать пересчитать сбережения через инвест
A4: 1996 | B4: 449174 | C4: -2623 | D4: =B4-C4 -> 451797 | E4: ='ВВП (расходы)'!E4+'ВВП (расходы)'!I4 -> 413970.1 | F4: ='ВВП (расходы)'!G4-'ВВП (расходы)'!H4 -> -8358.4 | G4: ='ГосБюджет'!S4 -> -342411.7 | H4: =E4-G4+F4 -> 748023.4 | I4: ='ВВП (расходы)'!E4+'ВВП (расходы)'!F4 -> 424380.9 | J4: ='ВВП (расходы)'!H4-'ВВП (расходы)'!G4 -> 8358.4 | K4: =I4-(D4+'ГосБюджет'!S4+J4) -> 306637.2 | L4: =E4-(H4+G4+J4) -> 0
A5: 1997 | B5: 447250 | C5: 4314 | D5: =B5-C5 -> 442936 | E5: ='ВВП (расходы)'!E5+'ВВП (расходы)'!I5 -> 425317.3 | F5: ='ВВП (расходы)'!G5-'ВВП (расходы)'!H5 -> 153.5 | G5: ='ГосБюджет'!S5 -> -374036.2 | H5: =E5-G5+F5 -> 799507 | I5: ='ВВП (расходы)'!E5+'ВВП (расходы)'!F5 -> 428719.1 | J5: ='ВВП (расходы)'!H5-'ВВП (расходы)'!G5 -> -153.5 | K5: =I5-(D5+'ГосБюджет'!S5+J5) -> 359972.8 | L5: =E5-(H5+G5+J5) -> 0
A6: 1998 | B6: 467658 | C6: 15299 | D6: =B6-C6 -> 452359 | E6: ='ВВП (расходы)'!E6+'ВВП (расходы)'!I6 -> 448761.9 | F6: ='ВВП (расходы)'!G6-'ВВП (расходы)'!H6 -> 2160.6 | G6: ='ГосБюджет'!S6 -> -376254.6 | H6: =E6-G6+F6 -> 827177.1 | I6: ='ВВП (расходы)'!E6+'ВВП (расходы)'!F6 -> 458598.3 | J6: ='ВВП (расходы)'!H6-'ВВП (расходы)'!G6 -> -2160.6 | K6: =I6-(D6+'ГосБюджет'!S6+J6) -> 384654.5 | L6: =E6-(H6+G6+J6) -> 0
A7: 1999 | B7: 463747 | C7: 32342 | D7: =B7-C7 -> 431405 | E7: ='ВВП (расходы)'!E7+'ВВП (расходы)'!I7 -> 465341 | F7: ='ВВП (расходы)'!G7-'ВВП (расходы)'!H7 -> 7078.1 | G7: ='ГосБюджет'!S7 -> -379384.4 | H7: =E7-G7+F7 -> 851803.5 | I7: ='ВВП (расходы)'!E7+'ВВП (расходы)'!F7 -> 485418.6 | J7: ='ВВП (расходы)'!H7-'ВВП (расходы)'!G7 -> -7078.1 | K7: =I7-(D7+'ГосБюджет'!S7+J7) -> 440476.1 | L7: =E7-(H7+G7+J7) -> 0
A8: 2000 | B8: 472328 | C8: 40845 | D8: =B8-C8 -> 431483 | E8: ='ВВП (расходы)'!E8+'ВВП (расходы)'!I8 -> 452996.2 | F8: ='ВВП (расходы)'!G8-'ВВП (расходы)'!H8 -> 13051.9 | G8: ='ГосБюджет'!S8 -> -370780.5 | H8: =E8-G8+F8 -> 836828.6 | I8: ='ВВП (расходы)'!E8+'ВВП (расходы)'!F8 -> 463415.8 | J8: ='ВВП (расходы)'!H8-'ВВП (расходы)'!G8 -> -13051.9 | K8: =I8-(D8+'ГосБюджет'!S8+J8) -> 415765.2 | L8: =E8-(H8+G8+J8) -> 0
A9: 2001 | B9: 490656 | C9: 11149 | D9: =B9-C9 -> 479507 | E9: ='ВВП (расходы)'!E9+'ВВП (расходы)'!I9 -> 442112.1 | F9: ='ВВП (расходы)'!G9-'ВВП (расходы)'!H9 -> 20026.5 | G9: ='ГосБюджет'!S9 -> -392420.8 | H9: =E9-G9+F9 -> 854559.4 | I9: ='ВВП (расходы)'!E9+'ВВП (расходы)'!F9 -> 458415.9 | J9: ='ВВП (расходы)'!H9-'ВВП (расходы)'!G9 -> -20026.5 | K9: =I9-(D9+'ГосБюджет'!S9+J9) -> 391356.2 | L9: =E9-(H9+G9+J9) -> 0
A10: 2002 | B10: 486509 | C10: -9569 | D10: =B10-C10 -> 496078 | E10: ='ВВП (расходы)'!E10+'ВВП (расходы)'!I10 -> 455981.6 | F10: ='ВВП (расходы)'!G10-'ВВП (расходы)'!H10 -> 23397.9 | G10: ='ГосБюджет'!S10 -> -413766.2 | H10: =E10-G10+F10 -> 893145.7 | I10: ='ВВП (расходы)'!E10+'ВВП (расходы)'!F10 -> 483297.9 | J10: ='ВВП (расходы)'!H10-'ВВП (расходы)'!G10 -> -23397.9 | K10: =I10-(D10+'ГосБюджет'!S10+J10) -> 424384 | L10: =E10-(H10+G10+J10) -> 0
A11: 2003 | B11: 466923 | C11: -12988 | D11: =B11-C11 -> 479911 | E11: ='ВВП (расходы)'!E11+'ВВП (расходы)'!I11 -> 474306 | F11: ='ВВП (расходы)'!G11-'ВВП (расходы)'!H11 -> 11228 | G11: ='ГосБюджет'!S11 -> -440438 | H11: =E11-G11+F11 -> 925972 | I11: ='ВВП (расходы)'!E11+'ВВП (расходы)'!F11 -> 493518 | J11: ='ВВП (расходы)'!H11-'ВВП (расходы)'!G11 -> -11228 | K11: =I11-(D11+'ГосБюджет'!S11+J11) -> 465273 | L11: =E11-(H11+G11+J11) -> 0
A12: 2004 | B12: 534870 | C12: -12977 | D12: =B12-C12 -> 547847 | E12: ='ВВП (расходы)'!E12+'ВВП (расходы)'!I12 -> 487329 | F12: ='ВВП (расходы)'!G12-'ВВП (расходы)'!H12 -> 3529 | G12: ='ГосБюджет'!S12 -> -446132 | H12: =E12-G12+F12 -> 936990 | I12: ='ВВП (расходы)'!E12+'ВВП (расходы)'!F12 -> 510351 | J12: ='ВВП (расходы)'!H12-'ВВП (расходы)'!G12 -> -3529 | K12: =I12-(D12+'ГосБюджет'!S12+J12) -> 412165 | L12: =E12-(H12+G12+J12) -> 0
A13: 2005 | B13: 539084 | C13: -3579 | D13: =B13-C13 -> 542663 | E13: ='ВВП (расходы)'!E13+'ВВП (расходы)'!I13 -> 472991 | F13: ='ВВП (расходы)'!G13-'ВВП (расходы)'!H13 -> 34284 | G13: ='ГосБюджет'!S13 -> -445532 | H13: =E13-G13+F13 -> 952807 | I13: ='ВВП (расходы)'!E13+'ВВП (расходы)'!F13 -> 499803 | J13: ='ВВП (расходы)'!H13-'ВВП (расходы)'!G13 -> -34284 | K13: =I13-(D13+'ГосБюджет'!S13+J13) -> 436956 | L13: =E13-(H13+G13+J13) -> 0
A14: 2006 | B14: 618748 | C14: 32328 | D14: =B14-C14 -> 586420 | E14: ='ВВП (расходы)'!E14+'ВВП (расходы)'!I14 -> 442153 | F14: ='ВВП (расходы)'!G14-'ВВП (расходы)'!H14 -> 90009 | G14: ='ГосБюджет'!S14 -> -417720 | H14: =E14-G14+F14 -> 949882 | I14: ='ВВП (расходы)'!E14+'ВВП (расходы)'!F14 -> 448046 | J14: ='ВВП (расходы)'!H14-'ВВП (расходы)'!G14 -> -90009 | K14: =I14-(D14+'ГосБюджет'!S14+J14) -> 369355 | L14: =E14-(H14+G14+J14) -> 0
A15: 2007 | B15: 696540 | C15: 76317 | D15: =B15-C15 -> 620223 | E15: ='ВВП (расходы)'!E15+'ВВП (расходы)'!I15 -> 431667 | F15: ='ВВП (расходы)'!G15-'ВВП (расходы)'!H15 -> 81143 | G15: ='ГосБюджет'!S15 -> -369263 | H15: =E15-G15+F15 -> 882073 | I15: ='ВВП (расходы)'!E15+'ВВП (расходы)'!F15 -> 438675 | J15: ='ВВП (расходы)'!H15-'ВВП (расходы)'!G15 -> -81143 | K15: =I15-(D15+'ГосБюджет'!S15+J15) -> 268858 | L15: =E15-(H15+G15+J15) -> 0
... A32: 2024 | B32: 1173201 | C32: 73571 | D32: =B32-C32 -> 1099630 | E32: ='ВВП (расходы)'!E32+'ВВП (расходы)'!I32 -> 736476 | F32: ='ВВП (расходы)'!G32-'ВВП (расходы)'!H32 -> 184386 | G32: ='ГосБюджет'!S32 -> -644122 | H32: =E32-G32+F32 -> 1564984 | I32: ='ВВП (расходы)'!E32+'ВВП (расходы)'!F32 -> 747420 | J32: ='ВВП (расходы)'!H32-'ВВП (расходы)'!G32 -> -184386 | K32: =I32-(D32+'ГосБюджет'!S32+J32) -> 476298 | L32: =E32-(H32+G32+J32) -> 0

Sheet Платёжный баланс
A1: Year | B1: current account | C1: goods | D1: services | E1: capital account | F1: primary income | G1: secondary income | H1: Financial account - Balance of payments statistics - IV. Financial account - Net Financial account | I1: Financial account - Balance of payments statistics - IV. Financial account - Reserve assets | J1: Проверка | L1: Погрешность
C2: NX | E2: KA | F2: Prim | G2: Sec | H2: FA | I2: ΔRes | J2: ΔRes_calc = NX + (Prim + Sec) + KA - FA | K2: FA_exRes | L2: ΔRes_calc − ΔRes
A3: 1991 | B3: -18998 | C3: 18047 | D3: -25731 | E3: -2522 | F3: 14176 | G3: -25488 | H3: -23028 | I3: -4911 | J3: =(C3+D3)+(F3+G3)+E3-K3 -> -3401 | K3: =H3-I3 -> -18117 | L3: =J3-I3 -> 1510 | M3: =SUM(E3:G3) -> -13834
A4: 1992 | B4: -16807 | C4: 24233 | D4: -32526 | E4: -1274 | F4: 13659 | G4: -22173 | H4: -23114 | I4: 27041 | J4: =(C4+D4)+(F4+G4)+E4-K4 -> 32074 | K4: =H4-I4 -> -50155 | L4: =J4-I4 -> 5033 | M4: =SUM(E4:G4) -> -9788
A5: 1993 | B5: -13717 | C5: 35538 | D5: -35045 | E5: -1209 | F5: 10174 | G5: -24385 | H5: -35367 | I5: -11655 | J5: =(C5+D5)+(F5+G5)+E5-K5 -> 8785 | K5: =H5-I5 -> -23712 | L5: =J5-I5 -> 20440 | M5: =SUM(E5:G5) -> -15420
A6: 1994 | B6: -24082 | C6: 43236 | D6: -40773 | E6: -1380 | F6: 144 | G6: -26689 | H6: -46139 | I6: -1455 | J6: =(C6+D6)+(F6+G6)+E6-K6 -> 19222 | K6: =H6-I6 -> -44684 | L6: =J6-I6 -> 20677 | M6: =SUM(E6:G6) -> -27925
A7: 1995 | B7: -20311 | C7: 49929 | D7: -42794 | E7: -2209 | F7: -3195 | G7: -24250 | H7: -42815 | I7: 5294 | J7: =(C7+D7)+(F7+G7)+E7-K7 -> 25590 | K7: =H7-I7 -> -48109 | L7: =J7-I7 -> 20296 | M7: =SUM(E7:G7) -> -29654
A8: 1996 | B8: -9343 | C8: 57864 | D8: -44766 | E8: -2272 | F8: -387 | G8: -22054 | H8: -29005 | I8: -962 | J8: =(C8+D8)+(F8+G8)+E8-K8 -> 16428 | K8: =H8-I8 -> -28043 | L8: =J8-I8 -> 17390 | M8: =SUM(E8:G8) -> -24713
A9: 1997 | B9: -6758 | C9: 66119 | D9: -45679 | E9: -419 | F9: -4494 | G9: -22705 | H9: -25519 | I9: -3395 | J9: =(C9+D9)+(F9+G9)+E9-K9 -> 14946 | K9: =H9-I9 -> -22124 | L9: =J9-I9 -> 18341 | M9: =SUM(E9:G9) -> -27618
A10: 1998 | B10: -10064 | C10: 70425 | D10: -46550 | E10: -422 | F10: -10936 | G10: -23002 | H10: -28684 | I10: 3644 | J10: =(C10+D10)+(F10+G10)+E10-K10 -> 21843 | K10: =H10-I10 -> -32328 | L10: =J10-I10 -> 18199 | M10: =SUM(E10:G10) -> -34360
A11: 1999 | B11: -24039 | C11: 67034 | D11: -55466 | E11: -922 | F11: -14537 | G11: -21071 | H11: -11292 | I11: -12535 | J11: =(C11+D11)+(F11+G11)+E11-K11 -> -26205 | K11: =H11-I11 -> 1243 | L11: =J11-I11 -> -13670 | M11: =SUM(E11:G11) -> -36530
A12: 2000 | B12: -32459 | C12: 63133 | D12: -59284 | E12: 5084 | F12: -12267 | G12: -24041 | H12: -57232 | I12: -5844 | J12: =(C12+D12)+(F12+G12)+E12-K12 -> 24013 | K12: =H12-I12 -> -51388 | L12: =J12-I12 -> 29857 | M12: =SUM(E12:G12) -> -31224
A13: 2001 | B13: -3809 | C13: 99369 | D13: -64876 | E13: -3260 | F13: -15603 | G13: -22700 | H13: -11576 | I13: -6032 | J13: =(C13+D13)+(F13+G13)+E13-K13 -> -1526 | K13: =H13-I13 -> -5544 | L13: =J13-I13 -> 4506
A14: 2002 | B14: 43450 | C14: 138492 | D14: -48235 | E14: -4144 | F14: -23137 | G14: -23671 | H14: -5756 | I14: -2065 | J14: =(C14+D14)+(F14+G14)+E14-K14 -> 42996 | K14: =H14-I14 -> -3691 | L14: =J14-I14 -> 45061
A15: 2003 | B15: 33599 | C15: 126921 | D15: -45552 | E15: 5878 | F15: -22903 | G15: -24865 | H15: =31880 -> 31880 | I15: -445 | J15: =(C15+D15)+(F15+G15)+E15-K15 -> 7154 | K15: =H15-I15 -> 32325 | L15: =J15-I15 -> 7599
A16: 2004 | B16: 103518 | C16: 149033 | D16: -35023 | E16: -11 | F16: 13706 | G16: -24198 | H16: 97102 | I16: -1470 | J16: =(C16+D16)+(F16+G16)+E16-K16 -> 4935 | K16: =H16-I16 -> 98572 | L16: =J16-I16 -> 6405
A17: 2005 | B17: 108171 | C17: 152721 | D17: -37540 | E17: -2760 | F17: 18836 | G17: -25846 | H17: 80475 | I17: -2182 | J17: =(C17+D17)+(F17+G17)+E17-K17 -> 22754 | K17: =H17-I17 -> 82657 | L17: =J17-I17 -> 24936
A18: 2006 | B18: 140953 | C18: 157411 | D18: -31572 | E18: -1418 | F18: 40329 | G18: -25214 | H18: 142732 | I18: -2934 | J18: =(C18+D18)+(F18+G18)+E18-K18 -> -6130 | K18: =H18-I18 -> 145666 | L18: =J18-I18 -> -3196
A19: 2007 | B19: 169607 | C19: 194773 | D19: -31998 | E19: -1471 | F19: 36241 | G19: -29408 | H19: 165218 | I19: 953 | J19: =(C19+D19)+(F19+G19)+E19-K19 -> 3872 | K19: =H19-I19 -> 164265 | L19: =J19-I19 -> 2919
A20: 2008 | B20: 145027 | C20: 178851 | D20: -28541 | E20: -1826 | F20: 24763 | G20: -30045 | H20: 106582 | I20: 2008 | J20: =(C20+D20)+(F20+G20)+E20-K20 -> 38628 | K20: =H20-I20 -> 104574 | L20: =J20-I20 -> 36620
A21: 2009 | B21: 144787 | C21: 136636 | D21: -16961 | E21: -1798 | F21: 55894 | G21: -30781 | H21: 111873 | I21: 8648 | J21: =(C21+D21)+(F21+G21)+E21-K21 -> 39765 | K21: =H21-I21 -> 103225 | L21: =J21-I21 -> 31117
A22: 2010 | B22: 150210 | C22: 159327 | D22: -25147 | E22: 19 | F22: 52345 | G22: -36317 | H22: 73036 | I22: 1613 | J22: =(C22+D22)+(F22+G22)+E22-K22 -> 78804 | K22: =H22-I22 -> 71423 | L22: =J22-I22 -> 77191
A23: 2011 | B23: 172828 | C23: 164171 | D23: -30158 | E23: -1069 | F23: 70336 | G23: -31522 | H23: 101101 | I23: 2836 | J23: =(C23+D23)+(F23+G23)+E23-K23 -> 73493 | K23: =H23-I23 -> 98265 | L23: =J23-I23 -> 70657
A24: 2012 | B24: 201278 | C24: 200916 | D24: -31425 | E24: -2167 | F24: 67296 | G24: -35510 | H24: 131252 | I24: 1297 | J24: =(C24+D24)+(F24+G24)+E24-K24 -> 69155 | K24: =H24-I24 -> 129955 | L24: =J24-I24 -> 67858
A25: 2013 | B25: 192345 | C25: 199951 | D25: -34258 | E25: -2970 | F25: 66871 | G25: -40218 | H25: 200883 | I25: 838 | J25: =(C25+D25)+(F25+G25)+E25-K25 -> -10669 | K25: =H25-I25 -> 200045 | L25: =J25-I25 -> -11507
A26: 2014 | B26: 215933 | C26: 218515 | D26: -22941 | E26: 335 | F26: 61801 | G26: -41442 | H26: 231400 | I26: -2564 | J26: =(C26+D26)+(F26+G26)+E26-K26 -> -17696 | K26: =H26-I26 -> 233964 | L26: =J26-I26 -> -15132
A27: 2015 | B27: 250087 | C27: 245055 | D27: -16237 | E27: -1769 | F27: 60039 | G27: -38770 | H27: 227420 | I27: -2213 | J27: =(C27+D27)+(F27+G27)+E27-K27 -> 18685 | K27: =H27-I27 -> 229633 | L27: =J27-I27 -> 20898
... A36: 2024 | B36: 249743 | C36: 237570 | D36: -71599 | E36: -22856 | F36: 152300 | G36: -68528 | H36: 262217 | I36: -1440 | J36: =(C36+D36)+(F36+G36)+E36-K36 -> -36770 | K36: =H36-I36 -> 263657 | L36: =J36-I36 -> -35330

Sheet ГосБюджет
A1: period | B1: Annual – Million euro – General government – Interest, expenditure – Germany (Eurostat/gov_10a_main/A.MIO_EUR.S13.D41PAY.DE) | C1: Annual – Million euro – General government – Total general government expenditure – Germany (Eurostat/gov_10a_main/A.MIO_EUR.S13.TE.DE) | D1: Annual – Million euro – General government – Social benefits other than social transfers in kind, expenditure – Germany (Eurostat/gov_10a_main/A.MIO_EUR.S13.D62PAY.DE) | E1: Annual – Million euro – General government – Other current transfers, expenditure – Germany (Eurostat/gov_10a_main/A.MIO_EUR.S13.D7PAY.DE) | G1: Annual – Million euro – General government – Taxes on production and imports – Germany (Eurostat/gov_10a_taxag/A.MIO_EUR.S13.D2.DE) | H1: Annual – Million euro – General government – Taxes on products – Germany (Eurostat/gov_10a_taxag/A.MIO_EUR.S13.D21.DE) | I1: Annual – Million euro – General government – Value added type taxes (VAT) – Germany (Eurostat/gov_10a_taxag/A.MIO_EUR.S13.D211.DE) | J1: Annual – Million euro – General government – Taxes and duties on imports excluding VAT – Germany (Eurostat/gov_10a_taxag/A.MIO_EUR.S13.D212.DE) | K1: Annual – Million euro – General government – Taxes on products, except VAT and import taxes – Germany (Eurostat/gov_10a_taxag/A.MIO_EUR.S13.D214.DE) | L1: Annual – Million euro – General government – Other taxes on production – Germany (Eurostat/gov_10a_taxag/A.MIO_EUR.S13.D29.DE) | M1: Annual – Million euro – General government – Current taxes on income, wealth, etc. – Germany (Eurostat/gov_10a_taxag/A.MIO_EUR.S13.D5.DE) | N1: Annual – Million euro – General government – Taxes on income – Germany (Eurostat/gov_10a_taxag/A.MIO_EUR.S13.D51.DE) | O1: Annual – Million euro – General government – Other current taxes – Germany (Eurostat/gov_10a_taxag/A.MIO_EUR.S13.D59.DE) | P1: Annual – Million euro – General government – Capital taxes – Germany (Eurostat/gov_10a_taxag/A.MIO_EUR.S13.D91.DE)
B2: % (проц платежи по долгу) | C2: G (гос закупки) | D2: Social benefits other than in kind, payable | E2: Other current transfers, payable | F2: Tr (трансферты) | G2: Налоги на производство и импорт | H2: Taxes on products | I2: налог на добавленную стоимость | J2: Taxes and duties on imports excl. VAT | K2: Taxes on products, except VAT and import taxes | L2: Other taxes on production | M2: Current taxes on income, wealth, etc. | N2: Taxes on income | O2: Other current taxes | P2: Capital taxes | Q2: Tx | R2: T=Tx-Tr | S2: δ | T2: процент от ВВП
A3: 1995 | B3: 69497.6 | C3: ='ВВП (расходы)'!D3 -> 285553.8 | D3: 340620.8 | E3: 37612.5 | F3: =D3+E3 -> 378233.3 | G3: 205470 | H3: 193534 | I3: 125482.1 | J3: 11359.7 | K3: 56692.2 | L3: 11935.9 | M3: 236110.9 | N3: 221329.5 | O3: 14781.3 | P3: 1889.3 | Q3: =G3+M3+P3 -> 443470.2 | R3: =Q3-F3 -> 65236.9 | S3: =R3-C3-B3 -> -289814.5 | T3: =S3/'ВВП (расходы)'!B3*100 -> -19.092708
A4: 1996 | B4: 68387.5 | C4: ='ВВП (расходы)'!D4 -> 320475.5 | D4: 354007.4 | E4: 36940.3 | F4: =D4+E4 -> 390947.7 | G4: 202402.3 | H4: 190272.2 | I4: 124428.9 | J4: 12070.7 | K4: 53772.7 | L4: 12130.1 | M4: 232897 | N4: 217730.1 | O4: 15167 | P4: 2099.7 | Q4: =G4+M4+P4 -> 437399 | R4: =Q4-F4 -> 46451.3 | S4: =R4-C4-B4 -> -342411.7 | T4: =S4/'ВВП (расходы)'!B4*100 -> -20.685564
A5: 1997 | B5: 66510.4 | C5: ='ВВП (расходы)'!D5 -> 346620 | D5: 351986.8 | E5: 37135.7 | F5: =D5+E5 -> 389122.5 | G5: 199755.1 | H5: 187403.1 | I5: 122488.7 | J5: 12707.5 | K5: 52206.9 | L5: 12352 | M5: 226400.6 | N5: 214331.4 | O5: 12069.3 | P5: 2061 | Q5: =G5+M5+P5 -> 428216.7 | R5: =Q5-F5 -> 39094.2 | S5: =R5-C5-B5 -> -374036.2 | T5: =S5/'ВВП (расходы)'!B5*100 -> -21.072626
A6: 1998 | B6: 67307.4 | C6: ='ВВП (расходы)'!D6 -> 363721.8 | D6: 355060.9 | E6: 37733.5 | F6: =D6+E6 -> 392794.4 | G6: 206708.6 | H6: 193901.7 | I6: 128333.5 | J6: 12158.3 | K6: 53409.9 | L6: 12806.9 | M6: 238417 | N6: 226304.4 | O6: 12112.6 | P6: 2443.4 | Q6: =G6+M6+P6 -> 447569 | R6: =Q6-F6 -> 54774.6 | S6: =R6-C6-B6 -> -376254.6 | T6: =S6/'ВВП (расходы)'!B6*100 -> -20.142992
A7: 1999 | B7: 64274 | C7: ='ВВП (расходы)'!D7 -> 389434.4 | D7: 370411 | E7: 37823 | F7: =D7+E7 -> 408234 | G7: 223572 | H7: 209962 | I7: 137707 | J7: 12399 | K7: 59856 | L7: 13610 | M7: 255926 | N7: 244260 | O7: 11666 | P7: 3060 | Q7: =G7+M7+P7 -> 482558 | R7: =Q7-F7 -> 74324 | S7: =R7-C7-B7 -> -379384.4 | T7: =S7/'ВВП (расходы)'!B7*100 -> -19.130325
A8: 2000 | B8: 67540 | C8: ='ВВП (расходы)'!D8 -> 392800.5 | D8: 369133 | E8: 41680 | F8: =D8+E8 -> 410813 | G8: 229381 | H8: 215601 | I8: 140003 | J8: 14210 | K8: 61388 | L8: 13780 | M8: 268002 | N8: 256331 | O8: 11671 | P8: 2990 | Q8: =G8+M8+P8 -> 500373 | R8: =Q8-F8 -> 89560 | S8: =R8-C8-B8 -> -370780.5 | T8: =S8/'ВВП (расходы)'!B8*100 -> -18.770747
A9: 2001 | B9: 66201 | C9: ='ВВП (расходы)'!D9 -> 382919.8 | D9: 382938 | E9: 39551 | F9: =D9+E9 -> 422489 | G9: 233418 | H9: 219497 | I9: 139088 | J9: 16052 | K9: 64357 | L9: 13921 | M9: 242701 | N9: 229553 | O9: 13148 | P9: 3070 | Q9: =G9+M9+P9 -> 479189 | R9: =Q9-F9 -> 56700 | S9: =R9-C9-B9 -> -392420.8 | T9: =S9/'ВВП (расходы)'!B9*100 -> -20.03556
A10: 2002 | B10: 66135 | C10: ='ВВП (расходы)'!D10 -> 387074.2 | D10: 397992 | E10: 38252 | F10: =D10+E10 -> 436244 | G10: 235394 | H10: 221296 | I10: 136779 | J10: 14592 | K10: 69925 | L10: 14098 | M10: 237263 | N10: 224662 | O10: 12601 | P10: 3030 | Q10: =G10+M10+P10 -> 475687 | R10: =Q10-F10 -> 39443 | S10: =R10-C10-B10 -> -413766.2 | T10: =S10/'ВВП (расходы)'!B10*100 -> -20.599192
A11: 2003 | B11: 65075 | C11: ='ВВП (расходы)'!D11 -> 407595 | D11: 408988 | E11: 40927 | F11: =D11+E11 -> 449915 | G11: 240978 | H11: 226556 | I11: 137196 | J11: 15019 | K11: 74341 | L11: 14422 | M11: 237799 | N11: 225367 | O11: 12432 | P11: 3370 | Q11: =G11+M11+P11 -> 482147 | R11: =Q11-F11 -> 32232 | S11: =R11-C11-B11 -> -440438 | T11: =S11/'ВВП (расходы)'!B11*100 -> -21.203039
A12: 2004 | B12: 63816 | C12: ='ВВП (расходы)'!D12 -> 413966 | D12: 411118 | E12: 39520 | F12: =D12+E12 -> 450638 | G12: 239835 | H12: 225239 | I12: 137444 | J12: 14242 | K12: 73553 | L12: 14596 | M12: 238163 | N12: 225512 | O12: 12651 | P12: 4290 | Q12: =G12+M12+P12 -> 482288 | R12: =Q12-F12 -> 31650 | S12: =R12-C12-B12 -> -446132 | T12: =S12/'ВВП (расходы)'!B12*100 -> -20.948508
A13: 2005 | B13: 63494 | C13: ='ВВП (расходы)'!D13 -> 422652 | D13: 412615 | E13: 41983 | F13: =D13+E13 -> 454598 | G13: 242581 | H13: 227411 | I13: 139801 | J13: 13619 | K13: 73991 | L13: 15170 | M13: 248531 | N13: 234879 | O13: 13652 | P13: 4100 | Q13: =G13+M13+P13 -> 495212 | R13: =Q13-F13 -> 40614 | S13: =R13-C13-B13 -> -445532 | T13: =S13/'ВВП (расходы)'!B13*100 -> -20.292686
A14: 2006 | B14: 65218 | C14: ='ВВП (расходы)'!D14 -> 434366 | D14: 409260 | E14: 42321 | F14: =D14+E14 -> 451581 | G14: 252846 | H14: 237532 | I14: 147135 | J14: 13402 | K14: 76995 | L14: 15314 | M14: 276839 | N14: 262906 | O14: 13933 | P14: 3760 | Q14: =G14+M14+P14 -> 533445 | R14: =Q14-F14 -> 81864 | S14: =R14-C14-B14 -> -417720 | T14: =S14/'ВВП (расходы)'!B14*100 -> -18.787781
... A32: 2024 | B32: 45416 | C32: ='ВВП (расходы)'!D32 -> 769045 | D32: 703226 | E32: 90217 | F32: =D32+E32 -> 793443 | G32: 416878 | H32: 380428 | I32: 283533 | J32: 33169 | K32: 63726 | L32: 36450 | M32: 537560 | N32: 521949 | O32: 15611 | P32: 9344 | Q32: =G32+M32+P32 -> 963782 | R32: =Q32-F32 -> 170339 | S32: =R32-C32-B32 -> -644122 | T32: =S32/'ВВП (расходы)'!B32*100 -> -18.67226

Sheet Проверка
A1: Год | B1: Тождество: C+I+G+Ex - (C+T+Im) = 0
A2: 1991 | B2: ='ВВП (расходы)'!C3+'ВВП (расходы)'!F3+'ГосБюджет'!C3+'ВВП (расходы)'!G3-('ВВП (расходы)'!C3+'ГосБюджет'!R3+'ВВП (расходы)'!H3) -> 233705.9
A3: 1992 | B3: ='ВВП (расходы)'!C4+'ВВП (расходы)'!F4+'ГосБюджет'!C4+'ВВП (расходы)'!G4-('ВВП (расходы)'!C4+'ГосБюджет'!R4+'ВВП (расходы)'!H4) -> 276076.6
A4: 1993 | B4: ='ВВП (расходы)'!C5+'ВВП (расходы)'!F5+'ГосБюджет'!C5+'ВВП (расходы)'!G5-('ВВП (расходы)'!C5+'ГосБюджет'!R5+'ВВП (расходы)'!H5) -> 311081.1
A5: 1994 | B5: ='ВВП (расходы)'!C6+'ВВП (расходы)'!F6+'ГосБюджет'!C6+'ВВП (расходы)'!G6-('ВВП (расходы)'!C6+'ГосБюджет'!R6+'ВВП (расходы)'!H6) -> 320944.2
A6: 1995 | B6: ='ВВП (расходы)'!C7+'ВВП (расходы)'!F7+'ГосБюджет'!C7+'ВВП (расходы)'!G7-('ВВП (расходы)'!C7+'ГосБюджет'!R7+'ВВП (расходы)'!H7) -> 342266.1
A7: 1996 | B7: ='ВВП (расходы)'!C8+'ВВП (расходы)'!F8+'ГосБюджет'!C8+'ВВП (расходы)'!G8-('ВВП (расходы)'!C8+'ГосБюджет'!R8+'ВВП (расходы)'!H8) -> 326712
A8: 1997 | B8: ='ВВП (расходы)'!C9+'ВВП (расходы)'!F9+'ГосБюджет'!C9+'ВВП (расходы)'!G9-('ВВП (расходы)'!C9+'ГосБюджет'!R9+'ВВП (расходы)'!H9) -> 362550.1
A9: 1998 | B9: ='ВВП (расходы)'!C10+'ВВП (расходы)'!F10+'ГосБюджет'!C10+'ВВП (расходы)'!G10-('ВВП (расходы)'!C10+'ГосБюджет'!R10+'ВВП (расходы)'!H10) -> 398345.4
A10: 1999 | B10: ='ВВП (расходы)'!C11+'ВВП (расходы)'!F11+'ГосБюджет'!C11+'ВВП (расходы)'!G11-('ВВП (расходы)'!C11+'ГосБюджет'!R11+'ВВП (расходы)'!H11) -> 405803
A11: 2000 | B11: ='ВВП (расходы)'!C12+'ВВП (расходы)'!F12+'ГосБюджет'!C12+'ВВП (расходы)'!G12-('ВВП (расходы)'!C12+'ГосБюджет'!R12+'ВВП (расходы)'!H12) -> 408867
A12: 2001 | B12: ='ВВП (расходы)'!C13+'ВВП (расходы)'!F13+'ГосБюджет'!C13+'ВВП (расходы)'!G13-('ВВП (расходы)'!C13+'ГосБюджет'!R13+'ВВП (расходы)'!H13) -> 443134
A13: 2002 | B13: ='ВВП (расходы)'!C14+'ВВП (расходы)'!F14+'ГосБюджет'!C14+'ВВП (расходы)'!G14-('ВВП (расходы)'!C14+'ГосБюджет'!R14+'ВВП (расходы)'!H14) -> 448404
... A35: 2024 | B35: ='ВВП (расходы)'!C36+'ВВП (расходы)'!F36+'ГосБюджет'!C36+'ВВП (расходы)'!G36-('ВВП (расходы)'!C36+'ГосБюджет'!R36+'ВВП (расходы)'!H36) -> 176147

Sheet Рынок труда
A1: period | B1: Annual – Thousand persons – Total – From 20 to 64 years – Total – Germany (Eurostat/lfsa_agan/A.THS_PER.T.Y20-64.TOTAL.DE) | C1: Annual – Thousand persons – Total – From 20 to 64 years – Total – Germany (Eurostat/lfsa_egan/A.THS_PER.T.Y20-64.TOTAL.DE) | D1: Annual – Thousand persons – Total – From 20 to 64 years – Total – Germany (Eurostat/lfsa_ugan/A.THS_PER.T.Y20-64.TOTAL.DE) | E1: Annual – Thousand persons – Total – From 20 to 64 years – Total – Germany (Eurostat/lfsa_igan/A.THS_PER.T.Y20-64.TOTAL.DE) | H1: Annual – Chain linked volumes, index 2015=100 – Gross domestic product at market prices – Germany (Eurostat/nama_10_gdp/A.CLV_I15.B1GQ.DE) | M1: Annually – Rate – Germany (AMECO/ZNAWRU/DEU.1.0.0.0.ZNAWRU)
B2: Labour_force | C2: Employment | D2: Unemployment | E2: Inactive | F2: L = E + U | H2: Дефлятор ВВП | I2: Пересчет реального ВВП через дефлятор | J2: Годовой рост реального ВВП: g_t = (Y_real_t / Y_real_{t-1} - 1) * 100% | L2: u | M2: Естественный уровень безработицы u* | N2: Циклическая безработица (u-u*) | O2: (Y-Y*)/Y* | P2: Коэффициент Оукена β | Q2: (Y-Y*)/Y*+β(u-u*)=0 | S2: p_t - Уровень участия
A3: 1995 | B3: 37316.8 | C3: 34241.7 | D3: 3075 | E3: 13266.4 | F3: =C3+D3+E3 -> 50583.1 | H3: 76.322 | L3: =D3/B3*100 -> 8.2402564 | M3: 7.489 | N3: =L3-$M$34 -> 5.2402564 | O3: =(N4-N3)/N3 -> 0.13227792 | P3: =SLOPE(O3:O32,N3:N32) -> -5.7636709 | Q3: =O3+P3*N3 -> -30.070835 | S3: ='Рынок труда'!F3/('Рынок труда'!F3+'Рынок труда'!E3) -> 0.7922239
A4: 1996 | B4: 37441.4 | C4: 34096.6 | D4: 3344.8 | E4: 13293.6 | F4: =C4+D4+E4 -> 50735 | H4: 77.115 | I4: ='ВВП (расходы)'!B7/(H3/100) -> 2598408.2 | J4: =(#REF!/'ВВП (расходы)'!B7-1)*100 -> #REF! | L4: =D4/B4*100 -> 8.9334266 | M4: 7.747 | N4: =L4-$M$34 -> 5.9334266 | O4: =(N5-N4)/N4 -> 0.17729412 | P4: =SLOPE(O4:O33,N4:N33) -> -5.7479271 | Q4: =O4+P4*N4 -> -33.92761 | S4: ='Рынок труда'!F4/('Рынок труда'!F4+'Рынок труда'!E4) -> 0.79238028
A5: 1997 | B5: 37435.7 | C5: 33697.5 | D5: 3738.1 | E5: 12995 | F5: =C5+D5+E5 -> 50430.6 | H5: 78.545 | I5: ='ВВП (расходы)'!B9/(H5/100) -> 2493629.9 | J5: =(I5/'ВВП (расходы)'!B8-1)*100 -> 26.239907 | L5: =D5/B5*100 -> 9.9853883 | M5: 8.031 | N5: =L5-$M$34 -> 6.9853883 | O5: =(N6-N5)/N5 -> -0.0067101417 | P5: =SLOPE(O5:O34,N5:N34) -> -5.769188 | Q5: =O5+P5*N5 -> -40.306728 | S5: ='Рынок труда'!F5/('Рынок труда'!F5+'Рынок труда'!E5) -> 0.79511428
A6: 1998 | B6: 37635.4 | C6: 33895 | D6: 3740.4 | E6: 12982 | F6: =C6+D6+E6 -> 50617.4 | H6: 80.191 | I6: ='ВВП (расходы)'!B10/(H6/100) -> 2504835.5 | J6: =(I6/'ВВП (расходы)'!B9-1)*100 -> 27.887666 | L6: =D6/B6*100 -> 9.9385153 | M6: 8.249 | N6: =L6-$M$34 -> 6.9385153 | O6: =(N7-N6)/N6 -> -0.13558682 | P6: =SLOPE(O6:O35,N6:N35) -> -5.912576 | Q6: =O6+P6*N6 -> -41.160086 | S6: ='Рынок труда'!F6/('Рынок труда'!F6+'Рынок труда'!E6) -> 0.79587858
A7: 1999 | B7: 37811.7 | C7: 34409.5 | D7: 3402.2 | E7: 12748.7 | F7: =C7+D7+E7 -> 50560.4 | H7: 81.9 | I7: ='ВВП (расходы)'!B11/(H7/100) -> 2536312.6 | J7: =(I7/'ВВП (расходы)'!B10-1)*100 -> 26.26935 | L7: =D7/B7*100 -> 8.9977441 | M7: 8.426 | N7: =L7-$M$34 -> 5.9977441 | O7: =(N8-N7)/N7 -> -0.16835939 | P7: =SLOPE(O7:O36,N7:N36) -> -6.0777989 | Q7: =O7+P7*N7 -> -36.621442 | S7: ='Рынок труда'!F7/('Рынок труда'!F7+'Рынок труда'!E7) -> 0.79862769
A8: 2000 | B8: 37631.6 | C8: 34625.6 | D8: 3006 | E8: 12799.1 | F8: =C8+D8+E8 -> 50430.7 | H8: 84.256 | I8: ='ВВП (расходы)'!B12/(H8/100) -> 2527606.3 | J8: =(I8/'ВВП (расходы)'!B11-1)*100 -> 21.680997 | L8: =D8/B8*100 -> 7.9879676 | M8: 8.583 | N8: =L8-$M$34 -> 4.9879676 | O8: =(N9-N8)/N8 -> -0.016856987 | P8: =SLOPE(O8:O37,N8:N37) -> -6.1329564 | Q8: =O8+P8*N8 -> -30.607845 | S8: ='Рынок труда'!F8/('Рынок труда'!F8+'Рынок труда'!E8) -> 0.79757804
A9: 2001 | B9: 37825.7 | C9: 34836 | D9: 2989.7 | E9: 12610.4 | F9: =C9+D9+E9 -> 50436.1 | H9: 85.635 | I9: ='ВВП (расходы)'!B13/(H9/100) -> 2563823.2 | J9: =(I9/'ВВП (расходы)'!B12-1)*100 -> 20.386503 | L9: =D9/B9*100 -> 7.9038855 | M9: 8.734 | N9: =L9-$M$34 -> 4.9038855 | O9: =(N10-N9)/N9 -> 0.14611497 | P9: =SLOPE(O9:O38,N9:N38) -> -6.1072731 | Q9: =O9+P9*N9 -> -29.803253 | S9: ='Рынок труда'!F9/('Рынок труда'!F9+'Рынок труда'!E9) -> 0.79998255
A10: 2002 | B10: 37875.2 | C10: 34610.2 | D10: 3265 | E10: 12461.4 | F10: =C10+D10+E10 -> 50336.6 | H10: 85.439 | I10: ='ВВП (расходы)'!B14/(H10/100) -> 2602277.6 | J10: =(I10/'ВВП (расходы)'!B13-1)*100 -> 18.526171 | L10: =D10/B10*100 -> 8.6204165 | M10: 8.849 | N10: =L10-$M$34 -> 5.6204165 | O10: =(N11-N10)/N10 -> 0.2343461 | P10: =SLOPE(O10:O39,N10:N39) -> -6.0755976 | Q10: =O10+P10*N10 -> -33.913043 | S10: ='Рынок труда'!F10/('Рынок труда'!F10+'Рынок труда'!E10) -> 0.80156374
A11: 2003 | B11: 38087.9 | C11: 34302.9 | D11: 3785 | E11: 12040.7 | F11: =C11+D11+E11 -> 50128.6 | H11: 84.987 | I11: ='ВВП (расходы)'!B15/(H11/100) -> 2636650.3 | J11: =(I11/'ВВП (расходы)'!B14-1)*100 -> 18.588547 | L11: =D11/B11*100 -> 9.9375392 | M11: 8.917 | N11: =L11-$M$34 -> 6.9375392 | O11: =(N12-N11)/N11 -> 0.13715456 | P11: =SLOPE(O11:O40,N11:N40) -> -6.0997312 | Q11: =O11+P11*N11 -> -42.17997 | S11: ='Рынок труда'!F11/('Рынок труда'!F11+'Рынок труда'!E11) -> 0.80632402
A12: 2004 | B12: 38003.3 | C12: 33865.2 | D12: 4138.2 | E12: 11851.3 | F12: =C12+D12+E12 -> 49854.7 | H12: 85.974 | I12: ='ВВП (расходы)'!B16/(H12/100) -> 2667131.9 | J12: =(I12/'ВВП (расходы)'!B15-1)*100 -> 19.025349 | L12: =D12/B12*100 -> 10.889054 | M12: 8.899 | N12: =L12-$M$34 -> 7.8890544 | O12: =(N13-N12)/N12 -> 0.03465769 | P12: =SLOPE(O12:O41,N12:N41) -> -6.3786988 | Q12: =O12+P12*N12 -> -50.287244 | S12: ='Рынок труда'!F12/('Рынок труда'!F12+'Рынок труда'!E12) -> 0.80793926
A13: 2005 | B13: 38962.7 | C13: 34613.5 | D13: 4349.2 | E13: 10932.9 | F13: =C13+D13+E13 -> 49895.6 | H13: 86.736 | I13: ='ВВП (расходы)'!B17/(H13/100) -> 2681366.4 | J13: =(I13/'ВВП (расходы)'!B16-1)*100 -> 16.935005 | L13: =D13/B13*100 -> 11.162471 | M13: 8.784 | N13: =L13-$M$34 -> 8.1624708 | O13: =(N14-N13)/N13 -> -0.11450083 | P13: =SLOPE(O13:O42,N13:N42) -> -7.1817591 | Q13: =O13+P13*N13 -> -58.7354 | S13: ='Рынок труда'!F13/('Рынок труда'!F13+'Рынок труда'!E13) -> 0.82026682
A14: 2006 | B14: 39401.2 | C14: 35371.3 | D14: 4029.9 | E14: 10330.5 | F14: =C14+D14+E14 -> 49731.7 | H14: 90.08 | I14: ='ВВП (расходы)'!B18/(H14/100) -> 2693361.5 | J14: =(I14/'ВВП (расходы)'!B17-1)*100 -> 15.808138 | L14: =D14/B14*100 -> 10.227861 | M14: 8.521 | N14: =L14-$M$34 -> 7.2278611 | O14: =(N15-N14)/N14 -> -0.2244704 | P14: =SLOPE(O14:O43,N14:N43) -> -8.9626563 | Q14: =O14+P14*N14 -> -65.005305 | S14: ='Рынок труда'!F14/('Рынок труда'!F14+'Рынок труда'!E14) -> 0.8280033
A15: 2007 | B15: 39463.5 | C15: 36067.5 | D15: 3396 | E15: 10004.4 | F15: =C15+D15+E15 -> 49467.9 | H15: 92.684 | I15: ='ВВП (расходы)'!B19/(H15/100) -> 2742889.8 | J15: =(I15/'ВВП (расходы)'!B18-1)*100 -> 13.053847 | L15: =D15/B15*100 -> 8.6054202 | M15: 8.132 | N15: =L15-$M$34 -> 5.6054202 | O15: =(N16-N15)/N15 -> -0.19761158 | P15: =SLOPE(O15:O44,N15:N44) -> -11.688485 | Q15: =O15+P15*N15 -> -65.716479 | S15: ='Рынок труда'!F15/('Рынок труда'!F15+'Рынок труда'!E15) -> 0.83178051
A16: 2008 | B16: 39548 | C16: 36582.9 | D16: 2965.2 | E16: 9909.2 | F16: =C16+D16+E16 -> 49457.3 | H16: 93.527 | I16: ='ВВП (расходы)'!B20/(H16/100) -> 2768911.7 | J16: =(I16/'ВВП (расходы)'!B19-1)*100 -> 8.9170745 | L16: =D16/B16*100 -> 7.4977243 | M16: 7.659 | N16: =L16-$M$34 -> 4.4977243 | O16: =(N17-N16)/N16 -> 0.051057221 | P16: =SLOPE(O16:O45,N16:N45) -> -14.169696 | Q16: =O16+P16*N16 -> -63.680327 | S16: ='Рынок труда'!F16/('Рынок труда'!F16+'Рынок труда'!E16) -> 0.83308432
... A32: 2024 | B32: 41163.4 | C32: 39797 | D32: 1366.4 | E32: 7788.3 | F32: =C32+D32+E32 -> 48951.7 | H32: 107.594 | I32: ='ВВП (расходы)'!B36/(H32/100) -> 4001394.1 | J32: =(I32/'ВВП (расходы)'!B35-1)*100 -> -4.399801 | L32: =D32/B32*100 -> 3.3194537 | M32: 3.174 | N32: =L32-$M$34 -> 0.31945369 | O32: =(N33-N32)/N32 -> -1 | P32: =SLOPE(O32:O61,N32:N61) -> #DIV/0! | Q32: =O32+P32*N32 -> #DIV/0! | S32: ='Рынок труда'!F32/('Рынок труда'!F32+'Рынок труда'!E32) -> 0.86273705
M34: =3 -> 3

Sheet Динам модель
A1: period | E1: Автономные налоги | K1: проц ставка (надо вычитать инфляцию по ф Фишера) | O1: Ct​=Ca​+MPC⋅(Yt​−Tt​+Trt​) | W1: Yad = c*(M/Pad) + d | X1: Ylras = a | Y1: Psras = b или Ysras = e*P + f
B2: Y реал | C2: T=Tx-Tr | D2: t | E2: Ta-Tr | F2: Yd = Y - T + Tr | G2: MPC | H2: Ca | K2: r | L2: slope=-i | M2: I0 | N2: годовые темпы роста в % | O2: M1 | P2: ma=mg | Q2: A | R2: Y | S2: P | T2: инфляция | U2: реал ставка по Фишеру | V2: M/P | W2: c | X2: d | Y2: e | Z2: f
A3: 1995 | B3: 2598408.2 | C3: ='ГосБюджет'!R3 -> 65236.9 | D3: {=LINEST(C3:C32, B3:B32, TRUE, FALSE)} -> 0.13995642 | E3: -283653.69 | F3: =B3-C3+'ГосБюджет'!F3 -> 2911404.6 | G3: {=LINEST('ВВП (расходы)'!C7:C36, 'ВВП (расходы)'!B7:B36, TRUE, FALSE)} -> 0.47121363 | H3: 200384.54 | K3: 6.8505428 | L3: {=LINEST('ВВП (расходы)'!F7:F36, K3:K32, TRUE, FALSE)} -> 550.95131 | M3: 11636.133 | N3: 3.358333 | O3: 7.2900833e+11 | P3: =1/(1-$G$3*(1-D3)+I3) -> 1.681419 | Q3: =$H$3-$G$3*$E$3+$G$3*+'ГосБюджет'!F3+'ВВП (расходы)'!F7+'ВВП (расходы)'!D7+'ВВП (расходы)'!G7 -> 1347799.2 | R3: =Q3*$P$3 -> 2266215.2 | S3: =('Рынок труда'!H3/100) -> 0.76322 | V3: =O3/S3 -> 955174567403 | W3: {=LINEST(B3:B32,V3:V32,TRUE,FALSE)} -> 3.1113582e-07 | X3: 2149703.3 | Y3: {=LINEST(B3:B32,S3:S32,TRUE,FALSE)} -> 3617793.8 | Z3: -437976.2
A4: 1996 | B4: 2561512.4 | C4: ='ГосБюджет'!R4 -> 46451.3 | F4: =B4-C4+'ГосБюджет'!F4 -> 2906008.8 | K4: 6.2153783 | N4: 6.575 | O4: 8.0499167e+11 | Q4: =$H$3-$G$3*$E$3+$G$3*+'ГосБюджет'!F4+'ВВП (расходы)'!F8+'ВВП (расходы)'!D8+'ВВП (расходы)'!G8 -> 1361628 | R4: =Q4*$P$3 -> 2289467.2 | S4: =('Рынок труда'!H4/100) -> 0.77115 | T4: =S4/S3-1 -> 0.010390189 | U4: =((1 + K4/100) / (1 + T4) - 1) * 100 -> 5.1231291 | V4: =O4/S4 -> 1043884674404
A5: 1997 | B5: 2493629.9 | C5: ='ГосБюджет'!R5 -> 39094.2 | F5: =B5-C5+'ГосБюджет'!F5 -> 2843658.2 | K5: 5.6401378 | N5: 8.633333 | O5: 872875000000 | Q5: =$H$3-$G$3*$E$3+$G$3*+'ГосБюджет'!F5+'ВВП (расходы)'!F9+'ВВП (расходы)'!D9+'ВВП (расходы)'!G9 -> 1400436.4 | R5: =Q5*$P$3 -> 2354720.5 | S5: =('Рынок труда'!H5/100) -> 0.78545 | T5: =S5/S4-1 -> 0.018543733 | U5: =((1 + K5/100) / (1 + T5) - 1) * 100 -> 3.7168404 | V5: =O5/S5 -> 1111305620982
A6: 1998 | B6: 2504835.5 | C6: ='ГосБюджет'!R6 -> 54774.6 | F6: =B6-C6+'ГосБюджет'!F6 -> 2842855.3 | K6: 4.5738012 | N6: 8.7 | O6: 9.3063333e+11 | Q6: =$H$3-$G$3*$E$3+$G$3*+'ГосБюджет'!F6+'ВВП (расходы)'!F10+'ВВП (расходы)'!D10+'ВВП (расходы)'!G10 -> 1448950.1 | R6: =Q6*$P$3 -> 2436292.3 | S6: =('Рынок труда'!H6/100) -> 0.80191 | T6: =S6/S5-1 -> 0.02095614 | U6: =((1 + K6/100) / (1 + T6) - 1) * 100 -> 2.42732 | V6: =O6/S6 -> 1160520922963
A7: 1999 | B7: 2536312.6 | C7: ='ГосБюджет'!R7 -> 74324 | F7: =B7-C7+'ГосБюджет'!F7 -> 2870222.6 | K7: 4.4906097 | N7: 12.60833 | O7: =O6*(1+N8/100) -> 1004153366667 | Q7: =$H$3-$G$3*$E$3+$G$3*+'ГосБюджет'!F7+'ВВП (расходы)'!F11+'ВВП (расходы)'!D11+'ВВП (расходы)'!G11 -> 1493921.4 | R7: =Q7*$P$3 -> 2511907.9 | S7: =('Рынок труда'!H7/100) -> 0.819 | T7: =S7/S6-1 -> 0.021311619 | U7: =((1 + K7/100) / (1 + T7) - 1) * 100 -> 2.3102135 | V7: =O7/S7 -> 1226072486772
A8: 2000 | B8: 2527606.3 | C8: ='ГосБюджет'!R8 -> 89560 | F8: =B8-C8+'ГосБюджет'!F8 -> 2848859.3 | K8: 5.2639587 | N8: 7.9 | O8: =O7*(1+N9/100) -> 1042896947383 | Q8: =$H$3-$G$3*$E$3+$G$3*+'ГосБюджет'!F8+'ВВП (расходы)'!F12+'ВВП (расходы)'!D12+'ВВП (расходы)'!G12 -> 1596711.7 | R8: =Q8*$P$3 -> 2684741.4 | S8: =('Рынок труда'!H8/100) -> 0.84256 | T8: =S8/S7-1 -> 0.028766789 | U8: =((1 + K8/100) / (1 + T8) - 1) * 100 -> 2.3205257 | V8: =O8/S8 -> 1237771728284
A9: 2001 | B9: 2563823.2 | C9: ='ГосБюджет'!R9 -> 56700 | F9: =B9-C9+'ГосБюджет'!F9 -> 2929612.2 | K9: 4.8123011 | N9: 3.858333 | O9: =O8*(1+N10/100) -> 1123982185042 | Q9: =$H$3-$G$3*$E$3+$G$3*+'ГосБюджет'!F9+'ВВП (расходы)'!F13+'ВВП (расходы)'!D13+'ВВП (расходы)'!G13 -> 1653555.6 | R9: =Q9*$P$3 -> 2780319.8 | S9: =('Рынок труда'!H9/100) -> 0.85635 | T9: =S9/S8-1 -> 0.016366787 | U9: =((1 + K9/100) / (1 + T9) - 1) * 100 -> 3.1244846 | V9: =O9/S9 -> 1312526636355
A10: 2002 | B10: 2602277.6 | C10: ='ГосБюджет'!R10 -> 39443 | F10: =B10-C10+'ГосБюджет'!F10 -> 2999078.6 | K10: 4.7835796 | N10: 7.775 | O10: =O9*(1+N11/100) -> 1247432857567 | Q10: =$H$3-$G$3*$E$3+$G$3*+'ГосБюджет'!F10+'ВВП (расходы)'!F14+'ВВП (расходы)'!D14+'ВВП (расходы)'!G14 -> 1673345.1 | R10: =Q10*$P$3 -> 2813594.4 | S10: =('Рынок труда'!H10/100) -> 0.85439 | T10: =S10/S9-1 -> -0.0022887838 | U10: =((1 + K10/100) / (1 + T10) - 1) * 100 -> 5.0239567 | V10: =O10/S10 -> 1460027455339
A11: 2003 | B11: 2636650.3 | C11: ='ГосБюджет'!R11 -> 32232 | F11: =B11-C11+'ГосБюджет'!F11 -> 3054333.3 | K11: 4.0711425 | N11: 10.98333 | O11: =O10*(1+N12/100) -> 1371864285109 | Q11: =$H$3-$G$3*$E$3+$G$3*+'ГосБюджет'!F11+'ВВП (расходы)'!F15+'ВВП (расходы)'!D15+'ВВП (расходы)'!G15 -> 1692281.1 | R11: =Q11*$P$3 -> 2845433.6 | S11: =('Рынок труда'!H11/100) -> 0.84987 | T11: =S11/S10-1 -> -0.0052903241 | U11: =((1 + K11/100) / (1 + T11) - 1) * 100 -> 4.6246408 | V11: =O11/S11 -> 1614204860872
A12: 2004 | B12: 2667131.9 | C12: ='ГосБюджет'!R12 -> 31650 | F12: =B12-C12+'ГосБюджет'!F12 -> 3086119.9 | K12: 4.0371557 | N12: 9.975 | O12: =O11*(1+N13/100) -> 1515910035046 | Q12: =$H$3-$G$3*$E$3+$G$3*+'ГосБюджет'!F12+'ВВП (расходы)'!F16+'ВВП (расходы)'!D16+'ВВП (расходы)'!G16 -> 1765721.8 | R12: =Q12*$P$3 -> 2968918.2 | S12: =('Рынок труда'!H12/100) -> 0.85974 | T12: =S12/S11-1 -> 0.011613541 | U12: =((1 + K12/100) / (1 + T12) - 1) * 100 -> 2.8427867 | V12: =O12/S12 -> 1763219153518
A13: 2005 | B13: 2681366.4 | C13: ='ГосБюджет'!R13 -> 40614 | F13: =B13-C13+'ГосБюджет'!F13 -> 3095350.4 | K13: 4.8544948 | N13: 10.5 | O13: =O12*(1+N14/100) -> 1644636067241 | Q13: =$H$3-$G$3*$E$3+$G$3*+'ГосБюджет'!F13+'ВВП (расходы)'!F17+'ВВП (расходы)'!D17+'ВВП (расходы)'!G17 -> 1824078.8 | R13: =Q13*$P$3 -> 3067040.8 | S13: =('Рынок труда'!H13/100) -> 0.86736 | T13: =S13/S12-1 -> 0.0088631447 | U13: =((1 + K13/100) / (1 + T13) - 1) * 100 -> 3.9333187 | V13: =O13/S13 -> 1896140088592
A14: 2006 | B14: 2693361.5 | C14: ='ГосБюджет'!R14 -> 81864 | F14: =B14-C14+'ГосБюджет'!F14 -> 3063078.5 | K14: 3.7641253 | N14: 8.491667 | O14: =O13*(1+N15/100) -> 1748385187001 | Q14: =$H$3-$G$3*$E$3+$G$3*+'ГосБюджет'!F14+'ВВП (расходы)'!F18+'ВВП (расходы)'!D18+'ВВП (расходы)'!G18 -> 1950625.1 | R14: =Q14*$P$3 -> 3279818.2 | S14: =('Рынок труда'!H14/100) -> 0.9008 | T14: =S14/S13-1 -> 0.038553772 | U14: =((1 + K14/100) / (1 + T14) - 1) * 100 -> -0.087864413 | V14: =O14/S14 -> 1940924941164
A15: 2007 | B15: 2742889.8 | C15: ='ГосБюджет'!R15 -> 136991 | F15: =B15-C15+'ГосБюджет'!F15 -> 3051377.8 | K15: 4.216955 | N15: 6.308333 | O15: =O14*(1+N16/100) -> 1789617931833 | Q15: =$H$3-$G$3*$E$3+$G$3*+'ГосБюджет'!F15+'ВВП (расходы)'!F19+'ВВП (расходы)'!D19+'ВВП (расходы)'!G19 -> 2061247.8 | R15: =Q15*$P$3 -> 3465821.3 | S15: =('Рынок труда'!H15/100) -> 0.92684 | T15: =S15/S14-1 -> 0.028907638 | U15: =((1 + K15/100) / (1 + T15) - 1) * 100 -> 1.2889313 | V15: =O15/S15 -> 1930881200459
A16: 2008 | B16: 2768911.7 | C16: ='ГосБюджет'!R16 -> 148979 | F16: =B16-C16+'ГосБюджет'!F16 -> 3073069.7 | K16: 3.9847682 | N16: 2.358333 | O16: =O15*(1+N17/100) -> 1965000489153 | Q16: =$H$3-$G$3*$E$3+$G$3*+'ГосБюджет'!F16+'ВВП (расходы)'!F20+'ВВП (расходы)'!D20+'ВВП (расходы)'!G20 -> 2107385.4 | R16: =Q16*$P$3 -> 3543397.8 | S16: =('Рынок труда'!H16/100) -> 0.93527 | T16: =S16/S15-1 -> 0.009095421 | U16: =((1 + K16/100) / (1 + T16) - 1) * 100 -> 3.0475078 | V16: =O16/S16 -> 2100998095900
A17: 2009 | B17: 2824136 | C17: ='ГосБюджет'!R17 -> 98137 | F17: =B17-C17+'ГосБюджет'!F17 -> 3200675 | K17: 3.2222178 | N17: 9.8 | O17: =O16*(1+N18/100) -> 2128914286506 | Q17: =$H$3-$G$3*$E$3+$G$3*+'ГосБюджет'!F17+'ВВП (расходы)'!F21+'ВВП (расходы)'!D21+'ВВП (расходы)'!G21 -> 1920890.8 | R17: =Q17*$P$3 -> 3229822.4 | S17: =('Рынок труда'!H17/100) -> 0.88341 | T17: =S17/S16-1 -> -0.055449229 | U17: =((1 + K17/100) / (1 + T17) - 1) * 100 -> 9.2818099 | V17: =O17/S17 -> 2409882485489
A18: 2010 | B18: 2843388.9 | C18: ='ГосБюджет'!R18 -> 89269 | F18: =B18-C18+'ГосБюджет'!F18 -> 3237117.9 | K18: 2.7442674 | N18: 8.341667 | O18: =O17*(1+N19/100) -> 2172557029380 | Q18: =$H$3-$G$3*$E$3+$G$3*+'ГосБюджет'!F18+'ВВП (расходы)'!F22+'ВВП (расходы)'!D22+'ВВП (расходы)'!G22 -> 2116389.3 | R18: =Q18*$P$3 -> 3558537.2 | S18: =('Рынок труда'!H18/100) -> 0.92005 | T18: =S18/S17-1 -> 0.041475646 | U18: =((1 + K18/100) / (1 + T18) - 1) * 100 -> -1.3474124 | V18: =O18/S18 -> 2361346697875
... A32: 2024 | B32: 4001394.1 | C32: ='ГосБюджет'!R32 -> 170339 | F32: =B32-C32+'ГосБюджет'!F32 -> 4624498.1 | K32: 2.3210841 | N32: -3.36667 | O32: =O31*(1+N33/100) -> 4699638778166 | Q32: =$H$3-$G$3*$E$3+$G$3*+'ГосБюджет'!F32+'ВВП (расходы)'!F36+'ВВП (расходы)'!D36+'ВВП (расходы)'!G36 -> 3474968.2 | R32: =Q32*$P$3 -> 5842877.6 | S32: =('Рынок труда'!H32/100) -> 1.07594 | T32: =S32/S31-1 -> -0.0023829172 | U32: =((1 + K32/100) / (1 + T32) - 1) * 100 -> 2.5654892 | V32: =O32/S32 -> 4367937597046
C37: ='ГосБюджет'!R33
C38: ='ГосБюджет'!R34
C39: ='ГосБюджет'!R35
C40: ='ГосБюджет'!R36

Sheet Эконом рост
A1: t | B1: коэф-ты | C1: 1996 | D1: 1997 | E1: 1998 | F1: 1999 | G1: 2000 | H1: 2001 | I1: 2002 | J1: 2003 | K1: 2004 | L1: 2005 | M1: 2006 | N1: 2007 | O1: 2008 | P1: 2009 | Q1: 2010 | R1: 2011 | S1: 2012 | T1: 2013 | U1: 2014 | V1: 2015 | W1: 2016 | X1: 2017 | Y1: 2018 | Z1: 2019 | AA1: 2020 | AB1: 2021 | AC1: 2022 | AD1: 2023 | AE1: 2024 | AF1: 2025 | AG1: 2026 | AH1: 2027 | AI1: 2028 | AJ1: 2029 | AK1: 2030 | AL1: 2031 | AM1: 2032 | AN1: 2033 | AO1: 2034 | AP1: 2035 | AQ1: 2036 | AR1: 2037 | AS1: 2038 | AT1: 2039 | AU1: 2040 | AV1: 2041 | AW1: 2042 | AX1: 2043 | AY1: 2044 | AZ1: 2045 | BA1: 2046 | BB1: 2047 | BC1: 2048 | BD1: 2049 | BE1: 2050 | BF1: 2051 | BG1: 2052 | BH1: 2053 | BI1: 2054 | BJ1: 2055 | BK1: 2056 | BL1: 2057 | BM1: 2058 | BN1: 2059 | BO1: 2060 | BP1: 2061 | BQ1: 2062 | BR1: 2063 | BS1: 2064 | BT1: 2065 | BU1: 2066 | BV1: 2067 | BW1: 2068 | BX1: 2069 | BY1: 2070 | BZ1: 2071 | CA1: 2072 | CB1: 2073 | CC1: 2074 | CD1: 2075 | CE1: 2076 | CF1: 2077 | CG1: 2078 | CH1: 2079 | CI1: 2080 | CJ1: 2081 | CK1: 2082 | CL1: 2083 | CM1: 2084 | CN1: 2085 | CO1: 2086 | CP1: 2087 | CQ1: 2088 | CR1: 2089 | CS1: 2090 | CT1: 2091 | CU1: 2092 | CV1: 2093 | CW1: 2094 | CX1: 2095 | CY1: 2096 | CZ1: 2097 | DA1: 2098 | DB1: 2099 | DC1: 2100
A2: Y | C2: =C10 -> 2561512.4 | D2: =D6*(D3^$B$8)*(D5^$B$9) -> 2579213.5 | E2: =E6*(E3^$B$8)*(E5^$B$9) -> 2596015.4 | F2: =F6*(F3^$B$8)*(F5^$B$9) -> 2630715.3 | G2: =G6*(G3^$B$8)*(G5^$B$9) -> 2641466.2 | H2: =H6*(H3^$B$8)*(H5^$B$9) -> 2669680.6 | I2: =I6*(I3^$B$8)*(I5^$B$9) -> 2689955.9 | J2: =J6*(J3^$B$8)*(J5^$B$9) -> 2715826.8 | K2: =K6*(K3^$B$8)*(K5^$B$9) -> 2727774.7 | ... DC2: =DC6*(DC3^$B$8)*(DC5^$B$9) -> 9185468.8
A3: L | C3: 37441.4 | D3: 37435.6 | E3: 37435.6 | F3: 37811.7 | G3: 37631.6 | H3: 37825.7 | I3: 37875.2 | J3: 38087.9 | K3: 38003.4 | L3: 38962.7 | M3: 39401.2 | N3: 39463.5 | O3: 39548.1 | P3: 39648.7 | Q3: 38939.4 | R3: 39226.6 | S3: 39405 | T3: 39661 | U3: 39856.4 | V3: 40000.8 | W3: 40740 | X3: 40899.9 | Y3: 40921.8 | Z3: 41233.8 | AA3: 40643.4 | AB3: 39931.4 | AC3: 40575.3 | AD3: 40947 | AE3: 41163.4 | AF3: 41413.975 | AG3: 41434.16 | AH3: 41253.915 | AI3: 41015.458 | AJ3: 40711.301 | AK3: 40371.29 | AL3: 40012.521 | AM3: 39634.114 | AN3: 39293.328 | AO3: 38947.364 | AP3: 38648.039 | AQ3: 38382.377 | AR3: 38208.641 | AS3: 38108.692 | AT3: 38063.141 | AU3: 38089.87 | AV3: 38172.561 | AW3: 38250.762 | AX3: 38333.505 | AY3: 38406.642 | AZ3: 38423.256 | BA3: 38451.339 | BB3: 38466.02 | BC3: 38435.747 | BD3: 38401.11 | BE3: 38351.363 | BF3: 38307.822 | BG3: 38255.834 | BH3: 38188.499 | BI3: 38089.206 | BJ3: 37966.059 | BK3: 37812.551 | BL3: 37670.265 | BM3: 37509.323 | BN3: 37406.531 | BO3: 37318.796 | BP3: 37233.902 | BQ3: 37161.58 | BR3: 37089.791 | BS3: 36998.438 | BT3: 36894.169 | BU3: 36811.547 | BV3: 36739.317 | BW3: 36672.684 | BX3: 36638.03 | BY3: 36619.692 | BZ3: 36611.802 | CA3: 36605.976 | CB3: 36606.992 | CC3: 36617.777 | CD3: 36618.5 | CE3: 36613.848 | CF3: 36623.266 | CG3: 36619.17 | CH3: 36624.25 | CI3: 36612.813 | CJ3: 36593.84 | CK3: 36548.5 | CL3: 36490.132 | CM3: 36406.116 | CN3: 36320.727 | CO3: 36233.343 | CP3: 36149.796 | CQ3: 36065.376 | CR3: 35966.862 | CS3: 35901.606 | CT3: 35815.236 | CU3: 35727.899 | CV3: 35643.962 | CW3: 35564.01 | CX3: 35488.394 | CY3: 35417.811 | CZ3: 35352.447 | DA3: 35292.507 | DB3: 35237.986 | DC3: 35188.774 | DD3: 35144609 | DE3: 35104875
A4: L_fact | C4: 37441.4 | D4: 37435.6 | E4: 37635.4 | F4: 37811.7 | G4: 37631.6 | H4: 37825.7 | I4: 37875.2 | J4: 38087.9 | K4: 38003.4 | L4: 38962.7 | M4: 39401.2 | N4: 39463.5 | O4: 39548.1 | P4: 39648.7 | Q4: 38939.4 | R4: 39226.6 | S4: 39405 | T4: 39661 | U4: 39856.4 | V4: 40000.8 | W4: 40740 | X4: 40899.9 | Y4: 40921.8 | Z4: 41233.8 | AA4: 40643.4 | AB4: 39931.4 | AC4: 40575.3 | AD4: 40947 | AE4: 41163.4
A5: K | C5: =C20 / ($B$16 + $B$25) -> 14131090 | D5: =C5*(1-$B$16)+C11 -> 14011965 | E5: =D5*(1-$B$16)+D11 -> 13874244 | F5: =E5*(1-$B$16)+E11 -> 13749152 | G5: =F5*(1-$B$16)+F11 -> 13640822 | H5: =G5*(1-$B$16)+G11 -> 13537172 | I5: =H5*(1-$B$16)+H11 -> 13412647 | J5: =I5*(1-$B$16)+I11 -> 13259522 | K5: =J5*(1-$B$16)+J11 -> 13104467 | ... DC5: =DB5*(1-$B$16)+DB11 -> 31676838
A6: a=нтп | C6: =C10/(C3^$B$8 * C5^$B$9) -> 8.5754344 | D6: =C6*(1+$B$7) -> 8.6611887 | E6: =D6*(1+$B$7) -> 8.7478006 | F6: =E6*(1+$B$7) -> 8.8352786 | G6: =F6*(1+$B$7) -> 8.9236314 | H6: =G6*(1+$B$7) -> 9.0128677 | I6: =H6*(1+$B$7) -> 9.1029964 | J6: =I6*(1+$B$7) -> 9.1940264 | K6: =J6*(1+$B$7) -> 9.2859666 | ... DC6: =DB6*(1+$B$7) -> 24.136762
A7: delta_a | B7: 0.01
A8: alfa | B8: 0.65
A9: beta | B9: 0.35
A10: Y факт | C10: 2561512.4 | D10: 2493629.9 | E10: 2504835.5 | F10: 2536312.6 | G10: 2527606.3 | H10: 2563823.2 | I10: 2602277.6 | J10: 2636650.3 | K10: 2667131.9 | L10: 2681366.4 | M10: 2693361.5 | N10: 2742889.8 | O10: 2768911.7 | P10: 2824136 | Q10: 2843388.9 | R10: 2878433.3 | S10: 2919647.6 | T10: 2977909.3 | U10: 3034511.2 | V10: 3085650 | W10: 3124404.9 | X10: 3170281.6 | Y10: 3229420.4 | Z10: 3294512.4 | AA10: 3352335.2 | AB10: 3446315.1 | AC10: 3656232.7 | AD10: 3880863.4 | AE10: 4001394.1
A11: I | C11: =IF(C$1<=2024,C20,$B$17*C2) -> 587429.42 | D11: =IF(D$1<=2024,D20,$B$17*D2) -> 562877.46 | E11: =IF(E$1<=2024,E20,$B$17*E2) -> 568619.42 | F11: =IF(F$1<=2024,F20,$B$17*F2) -> 579128.21 | G11: =IF(G$1<=2024,G20,$B$17*G2) -> 578390.86 | H11: =IF(H$1<=2024,H20,$B$17*H2) -> 552333.74 | I11: =IF(I$1<=2024,I20,$B$17*I2) -> 517507.23 | J11: =IF(J$1<=2024,J20,$B$17*J2) -> 507921.21 | ... DC11: =IF(DC$1<=2024,DC20,$B$17*DC2) -> 2009655.4
A12: m | B12: =0.03065 -> 0.03065
A13: b | B13: =0.02222 -> 0.02222
A14: e | B14: 0
A15: Im | AC15: 1008034 | AD15: 476926 | AE15: 286371 | AF15: 243325 | AG15: 201432 | AH15: 155114 | AI15: 160622 | AJ15: 162143 | AK15: 162228 | AL15: 162178 | AM15: 162151 | AN15: 162009 | AO15: 183408 | AP15: 177584 | AQ15: 173236 | AR15: 170095 | AS15: 167799 | AT15: 167291 | AU15: 166817 | AV15: 166356 | AW15: 166289 | AX15: 166591 | AY15: 167015 | AZ15: 170371 | BA15: 170419 | BB15: 171392 | BC15: 170387 | BD15: 170647 | BE15: 171497 | BF15: 173820 | BG15: 175379 | BH15: 177484 | BI15: 175821 | BJ15: 176799 | BK15: 170832 | BL15: 168705 | BM15: 167695 | BN15: 165835 | BO15: 165082 | BP15: 166202 | BQ15: 166787 | BR15: 164297 | BS15: 162878 | BT15: 161965 | BU15: 158712 | BV15: 156918 | BW15: 155717 | BX15: 155288 | BY15: 154795 | BZ15: 154019 | CA15: 154008 | CB15: 154055 | CC15: 152711 | CD15: 153372 | CE15: 152186 | CF15: 153295 | CG15: 153562 | CH15: 155501 | CI15: 156194 | CJ15: 157991 | CK15: 157534 | CL15: 157089 | CM15: 156079 | CN15: 155461 | CO15: 156039 | CP15: 152298 | CQ15: 153486 | CR15: 152869 | CS15: 151849 | CT15: 150787 | CU15: 149708 | CV15: 148606 | CW15: 147510 | CX15: 146444 | CY15: 145400 | CZ15: 144409 | DA15: 143479 | DB15: 142639 | DC15: 141870
A16: Am | B16: 0.05
A17: MPS | B17: 0.21878638
A18: ВНК (GFCF) | C18: 452996.2 | D18: 442112.1 | E18: 455981.6 | F18: 474306 | G18: 487329 | H18: 472991 | I18: 442153 | J18: 431667 | K18: 431813 | L18: 436406 | M18: 472193 | N18: 501203 | O18: 516899 | P18: 469819 | Q18: 501768 | R18: 549605 | S18: 558913 | T18: 561175 | U18: 590405 | V18: 609619 | W18: 640443 | X18: 671086 | Y18: 714880 | Z18: 748216 | AA18: 736476 | AB18: 779205 | AC18: 858253 | AD18: 899880 | AE18: 898489
A19: дефлятор | C19: 77.115 | D19: 78.545 | E19: 80.191 | F19: 81.9 | G19: 84.256 | H19: 85.635 | I19: 85.439 | J19: 84.987 | K19: 85.974 | L19: 86.736 | M19: 90.08 | N19: 92.684 | O19: 93.527 | P19: 88.341 | Q19: 92.005 | R19: 95.462 | S19: 95.915 | T19: 96.285 | U19: 98.374 | V19: 100 | W19: 102.295 | X19: 105.073 | Y19: 106.246 | Z19: 107.296 | AA19: 102.902 | AB19: 106.678 | AC19: 108.14 | AD19: 107.851 | AE19: 107.594
A20: реал инвестиции | C20: =C18/(C19/100) -> 587429.42 | D20: =D18/(D19/100) -> 562877.46 | E20: =E18/(E19/100) -> 568619.42 | F20: =F18/(F19/100) -> 579128.21 | G20: =G18/(G19/100) -> 578390.86 | H20: =H18/(H19/100) -> 552333.74 | I20: =I18/(I19/100) -> 517507.23 | J20: =J18/(J19/100) -> 507921.21 | ... AE20: =AE18/(AE19/100) -> 835073.52
A21: ЧНК | C21: =C20 - $B$16 * C5 -> -119125.09 | D21: =D20 - $B$16 * D5 -> -137720.8 | E21: =E20 - $B$16 * E5 -> -125092.8 | F21: =F20 - $B$16 * F5 -> -108329.38 | G21: =G20 - $B$16 * G5 -> -103650.26 | H21: =H20 - $B$16 * H5 -> -124524.86 | I21: =I20 - $B$16 * I5 -> -153125.13 | J21: =J20 - $B$16 * J5 -> -155054.89 | ... AE21: =AE20 - $B$16 * AE5 -> 186552.99 | BZ21: =BZ20 - $B$16 * BZ5 -> -1078981.9 | CA21: =CA20 - $B$16 * CA5 -> -1092581.7 | CB21: =CB20 - $B$16 * CB5 -> -1106469.7 | CC21: =CC20 - $B$16 * CC5 -> -1120656.4 | CD21: =CD20 - $B$16 * CD5 -> -1135156.1 | CE21: =CE20 - $B$16 * CE5 -> -1149958.2 | CF21: =CF20 - $B$16 * CF5 -> -1165058.4 | CG21: =CG20 - $B$16 * CG5 -> -1180477.4 | ... DC21: =DC20 - $B$16 * DC5 -> -1583841.9
A23: Err_t | C23: =IF(C$1<=2024, (C2-C10)^2, 0) -> 0 | D23: =IF(D$1<=2024, (D2-D10)^2, 0) -> 7324549223 | E23: =IF(E$1<=2024, (E2-E10)^2, 0) -> 8313782202 | F23: =IF(F$1<=2024, (F2-F10)^2, 0) -> 8911870831 | G23: =IF(G$1<=2024, (G2-G10)^2, 0) -> 12964070865 | H23: =IF(H$1<=2024, (H2-H10)^2, 0) -> 11205796560 | I23: =IF(I$1<=2024, (I2-I10)^2, 0) -> 7687468730 | J23: =IF(J$1<=2024, (J2-J10)^2, 0) -> 6268914072 | ... DC23: =IF(DC$1<=2024, (DC2-DC10)^2, 0) -> 0
A24: Sum(err_t) | B24: =SUM(C23:DC23) -> 713963572446
A25: g | B25: =-0.00843 -> -0.00843
F28: 0 | G28: < alpha/beta < | H28: 1
A29: калибровка | B29: из статистики | F29: 0.02 | G29: Am | H29: 0.08
A30: alfa | B30: m | F30: 0.1 | G30: MPS | H30: 0.3
A31: beta | B31: b | F31: 0 | G31: delta_a | H31: 0.02
A32: a | B32: e
C34: 1008034
C35: 476926
C36: 286371
C37: 243325
C38: 201432 | Z38: 41413975
C39: 155114 | Z39: 41434160
C40: 160622 | Z40: 41253915
C41: 162143 | Z41: 41015458
C42: 162228 | Z42: 40711301
C43: 162178 | Z43: 40371290
C44: 162151 | Z44: 40012521
...

Sheet __OpenSolverCache__

Sheet __OpenSolver__
A1: =ModelSheet=Эконом рост!A:Z -> #ERROR!
A2: =OpenSolver_AdjNum=6 -> #NAME?
A3: =OpenSolver_ChosenSolver=NeosCBC -> #NAME?
A4: =OpenSolver_FastBuild=0 -> #NAME?
A5: =OpenSolver_LinearityCheck=1 -> #NAME?
A6: =solver_adj=Эконом рост!B8 -> #ERROR!
A7: =solver_adj1=Эконом рост!B9 -> #ERROR!
A8: =solver_adj2=Эконом рост!B16 -> #ERROR!
A9: =solver_adj3=Эконом рост!B17 -> #ERROR!
A10: =solver_adj4=Эконом рост!C5 -> #ERROR!
A11: =solver_adj5=Эконом рост!B7 -> #ERROR!
A12: =solver_lhs1=Эконом рост!B8 -> #ERROR!
A13: =solver_lhs10=Эконом рост!B7 -> #ERROR!
A14: =solver_lhs2=Эконом рост!B8 -> #ERROR!
A15: =solver_lhs3=Эконом рост!B9 -> #ERROR!
A16: =solver_lhs4=Эконом рост!B9 -> #ERROR!
A17: =solver_lhs5=Эконом рост!B16 -> #ERROR!
A18: =solver_lhs6=Эконом рост!B16 -> #ERROR!
A19: =solver_lhs7=Эконом рост!B17 -> #ERROR!
A20: =solver_lhs8=Эконом рост!B17 -> #ERROR!
A21: =solver_lhs9=Эконом рост!B7 -> #ERROR!
A22: =solver_neg=1 -> #NAME?
A23: =solver_num=10 -> #NAME?
A24: =solver_opt=Эконом рост!B24 -> #ERROR!
A25: =solver_rel1=1 -> #NAME?
A26: =solver_rel10=3 -> #NAME?
A27: =solver_rel2=3 -> #NAME?
A28: =solver_rel3=1 -> #NAME?
A29: =solver_rel4=3 -> #NAME?
A30: =solver_rel5=3 -> #NAME?
A31: =solver_rel6=1 -> #NAME?
A32: =solver_rel7=1 -> #NAME?
A33: =solver_rel8=3 -> #NAME?
A34: =solver_rel9=1 -> #NAME?
A35: =solver_rhs1=Эконом рост!H28 -> #ERROR!
A36: =solver_rhs10=Эконом рост!F31 -> #ERROR!
A37: =solver_rhs2=Эконом рост!F28 -> #ERROR!
A38: =solver_rhs3=Эконом рост!H28 -> #ERROR!
A39: =solver_rhs4=Эконом рост!F28 -> #ERROR!
A40: =solver_rhs5=Эконом рост!F29 -> #ERROR!
...

Sheet Прогнозы
